Workbook
Name Slicer_Containers_still_in_Yard: #N/A
Name Slicer_Risk_Level: #N/A
Name Slicer_Terminal: #N/A

Sheet Raw Data
B1: Container Dwell Risk — Raw Data
B2: Report (as-of) Date: | C2: 46259
A4: S.no | B4: Container ID | C4: Terminal | D4: Vessel | E4: Customer | F4: Type | G4: Discharge Date | H4: Free Time (days) | I4: Gate Out Date | J4: Free Time Finish Day | K4: Demurrage Rate/day | L4: Dwell Time | M4: Risk Level | N4: Demurrage Calculation$ | O4: Containers still in Yard
A5: 1 | B5: CNTR100000 | C5: Terminal C | D5: Maersk Kiel | E5: Redline Logistics | F5: 20GP | G5: 46249 | H5: 7 | J5: =G5+H5 -> 46256 | K5: 130 | L5: =MAX(0, IF(I5="", $C$2-J5, I5-J5)) -> 3 | M5: {=_xlfn.IFS(L5>=10,"HIGH",L5=0,"LOW",L5<=9,"MEDIUM")} -> MEDIUM | N5: {=_xlfn.IFS(M5="HIGH",K5*L5,M5="MEDIUM",K5*L5,M5="LOW","NA")} -> 390 | O5: =IF(I5="","still in yard","cleared") -> still in yard
A6: 2 | B6: CNTR100001 | C6: Terminal A | D6: COSCO Harmony | E6: Atlas Motors | F6: 20GP | G6: 46247 | H6: 6 | I6: 46253 | J6: =G6+H6 -> 46253 | K6: 60 | L6: =MAX(0, IF(I6="", $C$2-J6, I6-J6)) -> 0 | M6: {=_xlfn.IFS(L6>=10,"HIGH",L6=0,"LOW",L6<=9,"MEDIUM")} -> LOW | N6: {=_xlfn.IFS(M6="HIGH",K6*L6,M6="MEDIUM",K6*L6,M6="LOW","NA")} -> NA | O6: =IF(I6="","still in yard","cleared") -> cleared
A7: 3 | B7: CNTR100002 | C7: Terminal A | D7: OOCL Bergen | E7: Harbor Direct | F7: 20GP | G7: 46185 | H7: 7 | I7: 46197 | J7: =G7+H7 -> 46192 | K7: 75 | L7: =MAX(0, IF(I7="", $C$2-J7, I7-J7)) -> 5 | M7: {=_xlfn.IFS(L7>=10,"HIGH",L7=0,"LOW",L7<=9,"MEDIUM")} -> MEDIUM | N7: {=_xlfn.IFS(M7="HIGH",K7*L7,M7="MEDIUM",K7*L7,M7="LOW","NA")} -> 375 | O7: =IF(I7="","still in yard","cleared") -> cleared
A8: 4 | B8: CNTR100003 | C8: Terminal A | D8: COSCO Harmony | E8: BlueCrest Mfg | F8: 40HC | G8: 46205 | H8: 5 | I8: 46206 | J8: =G8+H8 -> 46210 | K8: 75 | L8: =MAX(0, IF(I8="", $C$2-J8, I8-J8)) -> 0 | M8: {=_xlfn.IFS(L8>=10,"HIGH",L8=0,"LOW",L8<=9,"MEDIUM")} -> LOW | N8: {=_xlfn.IFS(M8="HIGH",K8*L8,M8="MEDIUM",K8*L8,M8="LOW","NA")} -> NA | O8: =IF(I8="","still in yard","cleared") -> cleared
A9: 5 | B9: CNTR100004 | C9: Terminal A | D9: ZIM Voyager | E9: Harbor Direct | F9: 40GP | G9: 46211 | H9: 4 | I9: 46212 | J9: =G9+H9 -> 46215 | K9: 60 | L9: =MAX(0, IF(I9="", $C$2-J9, I9-J9)) -> 0 | M9: {=_xlfn.IFS(L9>=10,"HIGH",L9=0,"LOW",L9<=9,"MEDIUM")} -> LOW | N9: {=_xlfn.IFS(M9="HIGH",K9*L9,M9="MEDIUM",K9*L9,M9="LOW","NA")} -> NA | O9: =IF(I9="","still in yard","cleared") -> cleared
A10: 6 | B10: CNTR100005 | C10: Terminal A | D10: ZIM Voyager | E10: Atlas Motors | F10: 40RF | G10: 46171 | H10: 4 | I10: 46172 | J10: =G10+H10 -> 46175 | K10: 150 | L10: =MAX(0, IF(I10="", $C$2-J10, I10-J10)) -> 0 | M10: {=_xlfn.IFS(L10>=10,"HIGH",L10=0,"LOW",L10<=9,"MEDIUM")} -> LOW | N10: {=_xlfn.IFS(M10="HIGH",K10*L10,M10="MEDIUM",K10*L10,M10="LOW","NA")} -> NA | O10: =IF(I10="","still in yard","cleared") -> cleared
A11: 7 | B11: CNTR100006 | C11: Terminal C | D11: Evergreen Ace | E11: Atlas Motors | F11: 40GP | G11: 46169 | H11: 5 | J11: =G11+H11 -> 46174 | K11: 90 | L11: =MAX(0, IF(I11="", $C$2-J11, I11-J11)) -> 85 | M11: {=_xlfn.IFS(L11>=10,"HIGH",L11=0,"LOW",L11<=9,"MEDIUM")} -> HIGH | N11: {=_xlfn.IFS(M11="HIGH",K11*L11,M11="MEDIUM",K11*L11,M11="LOW","NA")} -> 7650 | O11: =IF(I11="","still in yard","cleared") -> still in yard
A12: 8 | B12: CNTR100007 | C12: Terminal D | D12: ONE Kestrel | E12: Pioneer Goods | F12: 40HC | G12: 46181 | H12: 4 | J12: =G12+H12 -> 46185 | K12: 110 | L12: =MAX(0, IF(I12="", $C$2-J12, I12-J12)) -> 74 | M12: {=_xlfn.IFS(L12>=10,"HIGH",L12=0,"LOW",L12<=9,"MEDIUM")} -> HIGH | N12: {=_xlfn.IFS(M12="HIGH",K12*L12,M12="MEDIUM",K12*L12,M12="LOW","NA")} -> 8140 | O12: =IF(I12="","still in yard","cleared") -> still in yard
A13: 9 | B13: CNTR100008 | C13: Terminal B | D13: ONE Kestrel | E13: BlueCrest Mfg | F13: 40RF | G13: 46205 | H13: 3 | I13: 46212 | J13: =G13+H13 -> 46208 | K13: 120 | L13: =MAX(0, IF(I13="", $C$2-J13, I13-J13)) -> 4 | M13: {=_xlfn.IFS(L13>=10,"HIGH",L13=0,"LOW",L13<=9,"MEDIUM")} -> MEDIUM | N13: {=_xlfn.IFS(M13="HIGH",K13*L13,M13="MEDIUM",K13*L13,M13="LOW","NA")} -> 480 | O13: =IF(I13="","still in yard","cleared") -> cleared
A14: 10 | B14: CNTR100009 | C14: Terminal C | D14: ONE Kestrel | E14: Coastal Imports | F14: 40RF | G14: 46184 | H14: 4 | J14: =G14+H14 -> 46188 | K14: 120 | L14: =MAX(0, IF(I14="", $C$2-J14, I14-J14)) -> 71 | M14: {=_xlfn.IFS(L14>=10,"HIGH",L14=0,"LOW",L14<=9,"MEDIUM")} -> HIGH | N14: {=_xlfn.IFS(M14="HIGH",K14*L14,M14="MEDIUM",K14*L14,M14="LOW","NA")} -> 8520 | O14: =IF(I14="","still in yard","cleared") -> still in yard
A15: 11 | B15: CNTR100010 | C15: Terminal C | D15: Yang Ming Peak | E15: Horizon Foods | F15: 20GP | G15: 46169 | H15: 5 | I15: 46181 | J15: =G15+H15 -> 46174 | K15: 90 | L15: =MAX(0, IF(I15="", $C$2-J15, I15-J15)) -> 7 | M15: {=_xlfn.IFS(L15>=10,"HIGH",L15=0,"LOW",L15<=9,"MEDIUM")} -> MEDIUM | N15: {=_xlfn.IFS(M15="HIGH",K15*L15,M15="MEDIUM",K15*L15,M15="LOW","NA")} -> 630 | O15: =IF(I15="","still in yard","cleared") -> cleared
A16: 12 | B16: CNTR100011 | C16: Terminal D | D16: ONE Kestrel | E16: Nova Retail | F16: 40RF | G16: 46213 | H16: 3 | I16: 46215 | J16: =G16+H16 -> 46216 | K16: 150 | L16: =MAX(0, IF(I16="", $C$2-J16, I16-J16)) -> 0 | M16: {=_xlfn.IFS(L16>=10,"HIGH",L16=0,"LOW",L16<=9,"MEDIUM")} -> LOW | N16: {=_xlfn.IFS(M16="HIGH",K16*L16,M16="MEDIUM",K16*L16,M16="LOW","NA")} -> NA | O16: =IF(I16="","still in yard","cleared") -> cleared
A17: 13 | B17: CNTR100012 | C17: Terminal A | D17: OOCL Bergen | E17: Summit Traders | F17: 40GP | G17: 46227 | H17: 6 | I17: 46234 | J17: =G17+H17 -> 46233 | K17: 110 | L17: =MAX(0, IF(I17="", $C$2-J17, I17-J17)) -> 1 | M17: {=_xlfn.IFS(L17>=10,"HIGH",L17=0,"LOW",L17<=9,"MEDIUM")} -> MEDIUM | N17: {=_xlfn.IFS(M17="HIGH",K17*L17,M17="MEDIUM",K17*L17,M17="LOW","NA")} -> 110 | O17: =IF(I17="","still in yard","cleared") -> cleared
A18: 14 | B18: CNTR100013 | C18: Terminal D | D18: COSCO Harmony | E18: Summit Traders | F18: 40GP | G18: 46203 | H18: 7 | J18: =G18+H18 -> 46210 | K18: 110 | L18: =MAX(0, IF(I18="", $C$2-J18, I18-J18)) -> 49 | M18: {=_xlfn.IFS(L18>=10,"HIGH",L18=0,"LOW",L18<=9,"MEDIUM")} -> HIGH | N18: {=_xlfn.IFS(M18="HIGH",K18*L18,M18="MEDIUM",K18*L18,M18="LOW","NA")} -> 5390 | O18: =IF(I18="","still in yard","cleared") -> still in yard
A19: 15 | B19: CNTR100014 | C19: Terminal C | D19: Hapag Lloyd Bern | E19: Atlas Motors | F19: 40GP | G19: 46248 | H19: 5 | J19: =G19+H19 -> 46253 | K19: 75 | L19: =MAX(0, IF(I19="", $C$2-J19, I19-J19)) -> 6 | M19: {=_xlfn.IFS(L19>=10,"HIGH",L19=0,"LOW",L19<=9,"MEDIUM")} -> MEDIUM | N19: {=_xlfn.IFS(M19="HIGH",K19*L19,M19="MEDIUM",K19*L19,M19="LOW","NA")} -> 450 | O19: =IF(I19="","still in yard","cleared") -> still in yard
A20: 16 | B20: CNTR100015 | C20: Terminal A | D20: Yang Ming Peak | E20: Harbor Direct | F20: 40GP | G20: 46225 | H20: 5 | J20: =G20+H20 -> 46230 | K20: 110 | L20: =MAX(0, IF(I20="", $C$2-J20, I20-J20)) -> 29 | M20: {=_xlfn.IFS(L20>=10,"HIGH",L20=0,"LOW",L20<=9,"MEDIUM")} -> HIGH | N20: {=_xlfn.IFS(M20="HIGH",K20*L20,M20="MEDIUM",K20*L20,M20="LOW","NA")} -> 3190 | O20: =IF(I20="","still in yard","cleared") -> still in yard
A21: 17 | B21: CNTR100016 | C21: Terminal C | D21: ZIM Voyager | E21: Harbor Direct | F21: 40HC | G21: 46242 | H21: 7 | I21: 46247 | J21: =G21+H21 -> 46249 | K21: 60 | L21: =MAX(0, IF(I21="", $C$2-J21, I21-J21)) -> 0 | M21: {=_xlfn.IFS(L21>=10,"HIGH",L21=0,"LOW",L21<=9,"MEDIUM")} -> LOW | N21: {=_xlfn.IFS(M21="HIGH",K21*L21,M21="MEDIUM",K21*L21,M21="LOW","NA")} -> NA | O21: =IF(I21="","still in yard","cleared") -> cleared
A22: 18 | B22: CNTR100017 | C22: Terminal D | D22: COSCO Harmony | E22: Redline Logistics | F22: 40RF | G22: 46207 | H22: 4 | J22: =G22+H22 -> 46211 | K22: 180 | L22: =MAX(0, IF(I22="", $C$2-J22, I22-J22)) -> 48 | M22: {=_xlfn.IFS(L22>=10,"HIGH",L22=0,"LOW",L22<=9,"MEDIUM")} -> HIGH | N22: {=_xlfn.IFS(M22="HIGH",K22*L22,M22="MEDIUM",K22*L22,M22="LOW","NA")} -> 8640 | O22: =IF(I22="","still in yard","cleared") -> still in yard
A23: 19 | B23: CNTR100018 | C23: Terminal D | D23: MSC Elena | E23: Atlas Motors | F23: 20GP | G23: 46232 | H23: 6 | J23: =G23+H23 -> 46238 | K23: 90 | L23: =MAX(0, IF(I23="", $C$2-J23, I23-J23)) -> 21 | M23: {=_xlfn.IFS(L23>=10,"HIGH",L23=0,"LOW",L23<=9,"MEDIUM")} -> HIGH | N23: {=_xlfn.IFS(M23="HIGH",K23*L23,M23="MEDIUM",K23*L23,M23="LOW","NA")} -> 1890 | O23: =IF(I23="","still in yard","cleared") -> still in yard
A24: 20 | B24: CNTR100019 | C24: Terminal A | D24: CMA CGM Rhone | E24: Nova Retail | F24: 40GP | G24: 46190 | H24: 4 | I24: 46192 | J24: =G24+H24 -> 46194 | K24: 75 | L24: =MAX(0, IF(I24="", $C$2-J24, I24-J24)) -> 0 | M24: {=_xlfn.IFS(L24>=10,"HIGH",L24=0,"LOW",L24<=9,"MEDIUM")} -> LOW | N24: {=_xlfn.IFS(M24="HIGH",K24*L24,M24="MEDIUM",K24*L24,M24="LOW","NA")} -> NA | O24: =IF(I24="","still in yard","cleared") -> cleared
A25: 21 | B25: CNTR100020 | C25: Terminal D | D25: Maersk Kiel | E25: Summit Traders | F25: 40HC | G25: 46181 | H25: 5 | I25: 46184 | J25: =G25+H25 -> 46186 | K25: 60 | L25: =MAX(0, IF(I25="", $C$2-J25, I25-J25)) -> 0 | M25: {=_xlfn.IFS(L25>=10,"HIGH",L25=0,"LOW",L25<=9,"MEDIUM")} -> LOW | N25: {=_xlfn.IFS(M25="HIGH",K25*L25,M25="MEDIUM",K25*L25,M25="LOW","NA")} -> NA | O25: =IF(I25="","still in yard","cleared") -> cleared
A26: 22 | B26: CNTR100021 | C26: Terminal D | D26: Yang Ming Peak | E26: Pioneer Goods | F26: 40RF | G26: 46219 | H26: 3 | J26: =G26+H26 -> 46222 | K26: 180 | L26: =MAX(0, IF(I26="", $C$2-J26, I26-J26)) -> 37 | M26: {=_xlfn.IFS(L26>=10,"HIGH",L26=0,"LOW",L26<=9,"MEDIUM")} -> HIGH | N26: {=_xlfn.IFS(M26="HIGH",K26*L26,M26="MEDIUM",K26*L26,M26="LOW","NA")} -> 6660 | O26: =IF(I26="","still in yard","cleared") -> still in yard
A27: 23 | B27: CNTR100022 | C27: Terminal C | D27: Evergreen Ace | E27: Pioneer Goods | F27: 40GP | G27: 46192 | H27: 4 | J27: =G27+H27 -> 46196 | K27: 130 | L27: =MAX(0, IF(I27="", $C$2-J27, I27-J27)) -> 63 | M27: {=_xlfn.IFS(L27>=10,"HIGH",L27=0,"LOW",L27<=9,"MEDIUM")} -> HIGH | N27: {=_xlfn.IFS(M27="HIGH",K27*L27,M27="MEDIUM",K27*L27,M27="LOW","NA")} -> 8190 | O27: =IF(I27="","still in yard","cleared") -> still in yard
A28: 24 | B28: CNTR100023 | C28: Terminal C | D28: Maersk Kiel | E28: Vantage Traders | F28: 20GP | G28: 46191 | H28: 5 | I28: 46200 | J28: =G28+H28 -> 46196 | K28: 90 | L28: =MAX(0, IF(I28="", $C$2-J28, I28-J28)) -> 4 | M28: {=_xlfn.IFS(L28>=10,"HIGH",L28=0,"LOW",L28<=9,"MEDIUM")} -> MEDIUM | N28: {=_xlfn.IFS(M28="HIGH",K28*L28,M28="MEDIUM",K28*L28,M28="LOW","NA")} -> 360 | O28: =IF(I28="","still in yard","cleared") -> cleared
A29: 25 | B29: CNTR100024 | C29: Terminal C | D29: Maersk Kiel | E29: Coastal Imports | F29: 40GP | G29: 46190 | H29: 7 | I29: 46192 | J29: =G29+H29 -> 46197 | K29: 90 | L29: =MAX(0, IF(I29="", $C$2-J29, I29-J29)) -> 0 | M29: {=_xlfn.IFS(L29>=10,"HIGH",L29=0,"LOW",L29<=9,"MEDIUM")} -> LOW | N29: {=_xlfn.IFS(M29="HIGH",K29*L29,M29="MEDIUM",K29*L29,M29="LOW","NA")} -> NA | O29: =IF(I29="","still in yard","cleared") -> cleared
A30: 26 | B30: CNTR100025 | C30: Terminal B | D30: ZIM Voyager | E30: Atlas Motors | F30: 40GP | G30: 46207 | H30: 5 | J30: =G30+H30 -> 46212 | K30: 110 | L30: =MAX(0, IF(I30="", $C$2-J30, I30-J30)) -> 47 | M30: {=_xlfn.IFS(L30>=10,"HIGH",L30=0,"LOW",L30<=9,"MEDIUM")} -> HIGH | N30: {=_xlfn.IFS(M30="HIGH",K30*L30,M30="MEDIUM",K30*L30,M30="LOW","NA")} -> 5170 | O30: =IF(I30="","still in yard","cleared") -> still in yard
A31: 27 | B31: CNTR100026 | C31: Terminal C | D31: MSC Elena | E31: Nova Retail | F31: 40HC | G31: 46198 | H31: 5 | J31: =G31+H31 -> 46203 | K31: 130 | L31: =MAX(0, IF(I31="", $C$2-J31, I31-J31)) -> 56 | M31: {=_xlfn.IFS(L31>=10,"HIGH",L31=0,"LOW",L31<=9,"MEDIUM")} -> HIGH | N31: {=_xlfn.IFS(M31="HIGH",K31*L31,M31="MEDIUM",K31*L31,M31="LOW","NA")} -> 7280 | O31: =IF(I31="","still in yard","cleared") -> still in yard
A32: 28 | B32: CNTR100027 | C32: Terminal C | D32: Yang Ming Peak | E32: Coastal Imports | F32: 40HC | G32: 46248 | H32: 5 | J32: =G32+H32 -> 46253 | K32: 110 | L32: =MAX(0, IF(I32="", $C$2-J32, I32-J32)) -> 6 | M32: {=_xlfn.IFS(L32>=10,"HIGH",L32=0,"LOW",L32<=9,"MEDIUM")} -> MEDIUM | N32: {=_xlfn.IFS(M32="HIGH",K32*L32,M32="MEDIUM",K32*L32,M32="LOW","NA")} -> 660 | O32: =IF(I32="","still in yard","cleared") -> still in yard
A33: 29 | B33: CNTR100028 | C33: Terminal B | D33: ONE Kestrel | E33: Atlas Motors | F33: 40RF | G33: 46179 | H33: 4 | I33: 46180 | J33: =G33+H33 -> 46183 | K33: 180 | L33: =MAX(0, IF(I33="", $C$2-J33, I33-J33)) -> 0 | M33: {=_xlfn.IFS(L33>=10,"HIGH",L33=0,"LOW",L33<=9,"MEDIUM")} -> LOW | N33: {=_xlfn.IFS(M33="HIGH",K33*L33,M33="MEDIUM",K33*L33,M33="LOW","NA")} -> NA | O33: =IF(I33="","still in yard","cleared") -> cleared
A34: 30 | B34: CNTR100029 | C34: Terminal A | D34: CMA CGM Rhone | E34: Redline Logistics | F34: 40GP | G34: 46197 | H34: 5 | I34: 46202 | J34: =G34+H34 -> 46202 | K34: 90 | L34: =MAX(0, IF(I34="", $C$2-J34, I34-J34)) -> 0 | M34: {=_xlfn.IFS(L34>=10,"HIGH",L34=0,"LOW",L34<=9,"MEDIUM")} -> LOW | N34: {=_xlfn.IFS(M34="HIGH",K34*L34,M34="MEDIUM",K34*L34,M34="LOW","NA")} -> NA | O34: =IF(I34="","still in yard","cleared") -> cleared
A35: 31 | B35: CNTR100030 | C35: Terminal A | D35: Hapag Lloyd Bern | E35: Pioneer Goods | F35: 40RF | G35: 46248 | H35: 4 | J35: =G35+H35 -> 46252 | K35: 120 | L35: =MAX(0, IF(I35="", $C$2-J35, I35-J35)) -> 7 | M35: {=_xlfn.IFS(L35>=10,"HIGH",L35=0,"LOW",L35<=9,"MEDIUM")} -> MEDIUM | N35: {=_xlfn.IFS(M35="HIGH",K35*L35,M35="MEDIUM",K35*L35,M35="LOW","NA")} -> 840 | O35: =IF(I35="","still in yard","cleared") -> still in yard
A36: 32 | B36: CNTR100031 | C36: Terminal A | D36: Maersk Kiel | E36: Harbor Direct | F36: 40RF | G36: 46175 | H36: 3 | I36: 46176 | J36: =G36+H36 -> 46178 | K36: 150 | L36: =MAX(0, IF(I36="", $C$2-J36, I36-J36)) -> 0 | M36: {=_xlfn.IFS(L36>=10,"HIGH",L36=0,"LOW",L36<=9,"MEDIUM")} -> LOW | N36: {=_xlfn.IFS(M36="HIGH",K36*L36,M36="MEDIUM",K36*L36,M36="LOW","NA")} -> NA | O36: =IF(I36="","still in yard","cleared") -> cleared
A37: 33 | B37: CNTR100032 | C37: Terminal B | D37: COSCO Harmony | E37: Vantage Traders | F37: 40GP | G37: 46256 | H37: 4 | I37: 46257 | J37: =G37+H37 -> 46260 | K37: 60 | L37: =MAX(0, IF(I37="", $C$2-J37, I37-J37)) -> 0 | M37: {=_xlfn.IFS(L37>=10,"HIGH",L37=0,"LOW",L37<=9,"MEDIUM")} -> LOW | N37: {=_xlfn.IFS(M37="HIGH",K37*L37,M37="MEDIUM",K37*L37,M37="LOW","NA")} -> NA | O37: =IF(I37="","still in yard","cleared") -> cleared
A38: 34 | B38: CNTR100033 | C38: Terminal B | D38: Hapag Lloyd Bern | E38: Atlas Motors | F38: 40GP | G38: 46255 | H38: 5 | J38: =G38+H38 -> 46260 | K38: 130 | L38: =MAX(0, IF(I38="", $C$2-J38, I38-J38)) -> 0 | M38: {=_xlfn.IFS(L38>=10,"HIGH",L38=0,"LOW",L38<=9,"MEDIUM")} -> LOW | N38: {=_xlfn.IFS(M38="HIGH",K38*L38,M38="MEDIUM",K38*L38,M38="LOW","NA")} -> NA | O38: =IF(I38="","still in yard","cleared") -> still in yard
A39: 35 | B39: CNTR100034 | C39: Terminal B | D39: ZIM Voyager | E39: Coastal Imports | F39: 40HC | G39: 46189 | H39: 6 | I39: 46201 | J39: =G39+H39 -> 46195 | K39: 110 | L39: =MAX(0, IF(I39="", $C$2-J39, I39-J39)) -> 6 | M39: {=_xlfn.IFS(L39>=10,"HIGH",L39=0,"LOW",L39<=9,"MEDIUM")} -> MEDIUM | N39: {=_xlfn.IFS(M39="HIGH",K39*L39,M39="MEDIUM",K39*L39,M39="LOW","NA")} -> 660 | O39: =IF(I39="","still in yard","cleared") -> cleared
A40: 36 | B40: CNTR100035 | C40: Terminal D | D40: COSCO Harmony | E40: BlueCrest Mfg | F40: 40GP | G40: 46191 | H40: 7 | J40: =G40+H40 -> 46198 | K40: 110 | L40: =MAX(0, IF(I40="", $C$2-J40, I40-J40)) -> 61 | M40: {=_xlfn.IFS(L40>=10,"HIGH",L40=0,"LOW",L40<=9,"MEDIUM")} -> HIGH | N40: {=_xlfn.IFS(M40="HIGH",K40*L40,M40="MEDIUM",K40*L40,M40="LOW","NA")} -> 6710 | O40: =IF(I40="","still in yard","cleared") -> still in yard
A41: 37 | B41: CNTR100036 | C41: Terminal B | D41: ZIM Voyager | E41: Nova Retail | F41: 40GP | G41: 46236 | H41: 5 | I41: 46243 | J41: =G41+H41 -> 46241 | K41: 60 | L41: =MAX(0, IF(I41="", $C$2-J41, I41-J41)) -> 2 | M41: {=_xlfn.IFS(L41>=10,"HIGH",L41=0,"LOW",L41<=9,"MEDIUM")} -> MEDIUM | N41: {=_xlfn.IFS(M41="HIGH",K41*L41,M41="MEDIUM",K41*L41,M41="LOW","NA")} -> 120 | O41: =IF(I41="","still in yard","cleared") -> cleared
...

Sheet Terminal Performance
A2: S.No | B2: Terminal Name | C2: Count of containers | D2: Average dwell time | E2: Count of containers at high risk | F2: Estimated demurrage for high risk containers $ | G2: Percentage of Risk
A3: 1 | B3: Terminal A | C3: =COUNTIFS('Raw Data'!$C$5:$C$1504,B3) -> 364 | D3: =AVERAGEIF('Raw Data'!$C$5:$C$1504,B3,'Raw Data'!$L$5:$L$1504) -> 14.717033 | E3: =COUNTIFS('Raw Data'!$C$5:$C$1504,B3,'Raw Data'!$M$5:$M$1504,"HIGH") -> 101 | F3: =SUMIFS('Raw Data'!$N$5:$N$1504,'Raw Data'!$C$5:$C$1504,B3,'Raw Data'!$M$5:$M$1504,"HIGH") -> 565650 | G3: =E3/C3 -> 0.27747253
A4: 2 | B4: Terminal B | C4: =COUNTIFS('Raw Data'!$C$5:$C$1505,B4) -> 361 | D4: =AVERAGEIF('Raw Data'!$C$5:$C$1505,B4,'Raw Data'!$L$5:$L$1505) -> 14.750693 | E4: =COUNTIFS('Raw Data'!$C$5:$C$1505,B4,'Raw Data'!$M$5:$M$1505,"HIGH") -> 104 | F4: =SUMIFS('Raw Data'!$N$5:$N$1504,'Raw Data'!$C$5:$C$1504,B4,'Raw Data'!$M$5:$M$1504,"HIGH") -> 526605 | G4: =E4/C4 -> 0.28808864
A5: 3 | B5: Terminal C | C5: =COUNTIFS('Raw Data'!$C$5:$C$1506,B5) -> 385 | D5: =AVERAGEIF('Raw Data'!$C$5:$C$1506,B5,'Raw Data'!$L$5:$L$1506) -> 13.153247 | E5: =COUNTIFS('Raw Data'!$C$5:$C$1506,B5,'Raw Data'!$M$5:$M$1506,"HIGH") -> 96 | F5: =SUMIFS('Raw Data'!$N$5:$N$1504,'Raw Data'!$C$5:$C$1504,B5,'Raw Data'!$M$5:$M$1504,"HIGH") -> 521685 | G5: =E5/C5 -> 0.24935065
A6: 4 | B6: Terminal D | C6: =COUNTIFS('Raw Data'!$C$5:$C$1507,B6) -> 390 | D6: =AVERAGEIF('Raw Data'!$C$5:$C$1507,B6,'Raw Data'!$L$5:$L$1507) -> 13.151282 | E6: =COUNTIFS('Raw Data'!$C$5:$C$1507,B6,'Raw Data'!$M$5:$M$1507,"HIGH") -> 104 | F6: =SUMIFS('Raw Data'!$N$5:$N$1504,'Raw Data'!$C$5:$C$1504,B6,'Raw Data'!$M$5:$M$1504,"HIGH") -> 536175 | G6: =E6/C6 -> 0.26666667

Sheet KPI
A1: The KPIs, and why each one matters
A3: Average Dwell Time (days) — the core metric. How long, on average, a container sits before leaving the terminal. Rising trend = a systemic problem (customs delays, customer pickup issues, yard congestion).
A5: % Containers Over Free Time — the percentage that have blown past their free storage window and are now accruing demurrage charges. This is your headline risk number.
A7: Risk Category counts (High / Medium / Low) — buckets containers by how far over free time they are (10+ days = High, 1–9 = Medium, 0 = Low). Lets you triage: which containers need action today.
A9: Total Estimated Demurrage Exposure — the dollar cost of all the "Days Over" across every container. This is the number a manager actually cares about — it turns dwell time into a financial risk.
A11: Avg Demurrage Cost per At-Risk Container — helps you spot whether a few expensive containers are driving the total, or if it's spread evenly.
A13: Containers Still In Yard — how many haven't moved yet. High volume here + approaching free time deadlines = escalating risk pipeline.
A15: Avg Dwell by Terminal — surfaces operational bottlenecks (is one terminal consistently slower?).
A17: Demurrage Exposure by Customer — surfaces which customers are chronically slow to pick up their containers, useful for account management conversations.
A19: Highest Single Dwell Time — a quick outlier check, useful for catching a container that's been forgotten entirely.

Sheet Pivot table
A3: Terminals | B3: Average of Dwell Time | E3: Customers | F3: Average of Dwell Time | H3: Terminals | I3: Sum of Demurrage Calculation$ | K3: Terminals | L3: Count of Container ID
A4: Terminal A | B4: 14.717033 | E4: Atlas Motors | F4: 11.40113 | H4: Terminal A | I4: 602295 | K4: HIGH | L4: 405
A5: Terminal B | B5: 14.750693 | E5: BlueCrest Mfg | F5: 19.617391 | H5: Terminal B | I5: 560655 | K5: LOW | L5: 655
A6: Terminal C | B6: 13.153247 | E6: Coastal Imports | F6: 14.558333 | H6: Terminal C | I6: 567225 | K6: MEDIUM | L6: 440
A7: Terminal D | B7: 13.151282 | E7: Harbor Direct | F7: 11.96 | H7: Terminal D | I7: 577745 | K7: Grand Total | L7: 1500
A8: Grand Total | B8: 13.916667 | E8: Horizon Foods | F8: 17.759494 | H8: Grand Total | I8: 2307920
E9: Nova Retail | F9: 12.768786
E10: Pioneer Goods | F10: 12.088608
E11: Redline Logistics | F11: 13.328671
E12: Summit Traders | F12: 13.152318
E13: Vantage Traders | F13: 14.470968
E14: Grand Total | F14: 13.916667
A18: Customers | B18: Sum of Demurrage Calculation$ | E18: Count of Container ID | F18: Column Labels
A19: Atlas Motors | B19: 220000 | E19: Risk Level | F19: Terminal A | G19: Terminal B | H19: Terminal C | I19: Terminal D | J19: Grand Total
A20: BlueCrest Mfg | B20: 254100 | E20: HIGH | F20: 101 | G20: 104 | H20: 96 | I20: 104 | J20: 405
A21: Coastal Imports | B21: 186165 | E21: LOW | F21: 155 | G21: 152 | H21: 170 | I21: 178 | J21: 655
A22: Harbor Direct | B22: 200645 | E22: MEDIUM | F22: 108 | G22: 105 | H22: 119 | I22: 108 | J22: 440
A23: Horizon Foods | B23: 303065 | E23: Grand Total | F23: 364 | G23: 361 | H23: 385 | I23: 390 | J23: 1500
A24: Nova Retail | B24: 245450
A25: Pioneer Goods | B25: 221280
A26: Redline Logistics | B26: 222225
A27: Summit Traders | B27: 207490
A28: Vantage Traders | B28: 247500
A29: Grand Total | B29: 2307920

Sheet Dashboard
